Workbook

Sheet Executive Summary
A1: TUPENSACI | Business Plan 360° v3.0
A2: Base case | €9 / €89 / €69 | 7-day guided trial | Acceleration only after observed gates
A4: THREE-YEAR ECONOMIC VIEW | F4: ROUND & DEPLOYMENT
A5: Metric | B5: Year 1 | C5: Year 2 | D5: Year 3 | F5: Metric | G5: v3.0 plan
A6: Physical + extensions revenue | B6: =SUM('P&L 36 Months'!B10:M10) -> 364117.84 | C6: =SUM('P&L 36 Months'!N10:Y10) -> 556333.28 | D6: =SUM('P&L 36 Months'!Z10:AK10) -> 629195.72 | F6: Round committed | G6: =Assumptions!$C$47 -> 300000
A7: AI revenue | B7: =SUM('P&L 36 Months'!B11:M11) -> 121142.09 | C7: =SUM('P&L 36 Months'!N11:Y11) -> 337997.88 | D7: =SUM('P&L 36 Months'!Z11:AK11) -> 482450.09 | F7: Start tranche — M1 | G7: ='Capital Gates'!$C$5 -> 90000
A8: Total revenue | B8: =SUM('P&L 36 Months'!B12:M12) -> 485259.93 | C8: =SUM('P&L 36 Months'!N12:Y12) -> 894331.16 | D8: =SUM('P&L 36 Months'!Z12:AK12) -> 1111645.8 | F8: Post-M3 tranche | G8: ='Capital Gates'!$C$6 -> 80000
A9: Gross profit | B9: =SUM('P&L 36 Months'!B16:M16) -> 288357.95 | C9: =SUM('P&L 36 Months'!N16:Y16) -> 523224.57 | D9: =SUM('P&L 36 Months'!Z16:AK16) -> 644467.49 | F9: Post-M6 tranche | G9: ='Capital Gates'!$C$7 -> 115000
A10: Operating EBITDA before one-time build | B10: =SUM('P&L 36 Months'!B23:M23) -> 9357.9495 | C10: =SUM('P&L 36 Months'!N23:Y23) -> 163224.57 | D10: =SUM('P&L 36 Months'!Z23:AK23) -> 272467.49 | F10: Ring-fenced reserve | G10: =Assumptions!$C$48 -> 15000
A11: Cash operating result | B11: =SUM('P&L 36 Months'!B27:M27) -> -90642.051 | C11: =SUM('P&L 36 Months'!N27:Y27) -> 148224.57 | D11: =SUM('P&L 36 Months'!Z27:AK27) -> 257467.49 | F11: M12 decision | G11: Scale / correct / stop
F12: Verdict | G12: ='Cash & Funding'!B27 -> Base is funded with headroom; Accelerated deployment remains conditional on gates
A14: OPERATING KPIs & PROOF PLAN
A15: KPI | B15: Year 1 | C15: Year 2 | D15: Year 3 | F15: 1. Relaunch Diario, Crea and L’Arte with one accountable growth owner and specialist agency.
A16: Physical orders | B16: =SUM('Physical Business'!B14:M14) -> 10666.182 | C16: =SUM('Physical Business'!N14:Y14) -> 15160.414 | D16: =SUM('Physical Business'!Z14:AK14) -> 15924.866 | F16: 2. Keep the integrated Base prudent: ≈2,000 active AI users at M12 and ≈4,000 at M24.
A17: New physical buyers | B17: =SUM('Physical Business'!B15:M15) -> 10666.182 | C17: =SUM('Physical Business'!N15:Y15) -> 14093.796 | D17: =SUM('Physical Business'!Z15:AK15) -> 14515.487 | F17: 3. Launch at €9/month, €89/year and €69 founding for the first year; founding renews at €89.
A18: AI users acquired | B18: =SUM('AI Cohorts'!B15:M15) -> 2521.2241 | C18: =SUM('AI Cohorts'!N15:Y15) -> 4087.951 | D18: =SUM('AI Cohorts'!Z15:AK15) -> 4665.8344 | F18: 4. Use a guided 7-day no-card trial; no permanent free tier.
A19: AI active users at year end | B19: ='AI Cohorts'!M26 -> 2079.2872 | C19: ='AI Cohorts'!Y26 -> 3999.939 | D19: ='AI Cohorts'!AK26 -> 5152.4809 | F19: 5. Accelerate only after observed CAC ≤€20, churn ≤6%, acceptable safety and real return usage.
A20: AI ARR at year end | B20: ='AI Cohorts'!M42 -> 210192.04 | C20: ='AI Cohorts'!Y42 -> 402225.15 | D20: ='AI Cohorts'!AK42 -> 516476.97 | F20: 6. In the gated case, target ≈3,200 active users at M12 and ≈4,700–5,000 at M24.
A21: Physical → AI attach | B21: =Assumptions!$F$10 -> 0.1 | C21: =Assumptions!$F$10 -> 0.1 | D21: =Assumptions!$F$10 -> 0.1 | F21: 7. Collect the €300k round in full; authorize €90k / €80k / €115k and hold €15k in reserve.
A22: Effective monthly churn | B22: =Assumptions!$C$69 -> 0.08 | C22: =Assumptions!$C$69 -> 0.08 | D22: =Assumptions!$C$69 -> 0.08 | F22: 8. Keep one new workbook per year and early B2B pilots inside the ecosystem thesis.
A26: Year | B26: Physical | C26: AI | D26: EBITDA | F26: Year | G26: Ending cash
A27: Y1 | B27: =B6 -> 364117.84 | C27: =B7 -> 121142.09 | D27: =B10 -> 9357.9495 | F27: Y1 | G27: ='Cash & Funding'!M12 -> 209357.95
A28: Y2 | B28: =C6 -> 556333.28 | C28: =C7 -> 337997.88 | D28: =C10 -> 163224.57 | F28: Y2 | G28: ='Cash & Funding'!Y12 -> 357582.52
A29: Y3 | B29: =D6 -> 629195.72 | C29: =D7 -> 482450.09 | D29: =D10 -> 272467.49 | F29: Y3 | G29: ='Cash & Funding'!AK12 -> 615050.01

Sheet Assumptions
A1: TUPENSACI | Assumptions v3.0
A2: Base prudente con pricing €9/€89, offerta founding €69 e prova guidata di 7 giorni. Lo scenario Accelerato è separato e si attiva soltanto dopo evidenza su CAC, retention e qualità del prodotto.
A4: MODEL CONTROL | D4: BRANCH CONTROLS
A5: Scenario selected | B5: Base | D5: AI paid branch | E5: Test
D6: Growth extensions | E6: On
A7: SCENARIO DRIVERS
A8: Driver | B8: Unit | C8: Downside | D8: Base | E8: Upside | F8: Selected | G8: Rationale / source | H8: Status
A9: Historical customer → AI conversion | B9: % | C9: 0.01 | D9: 0.02 | E9: 0.04 | F9: =IF($B$5="Downside",C9,IF($B$5="Upside",E9,D9)) -> 0.02 | G9: Conservative reactivation of ~21k historical contacts | H9: Model assumption
A10: New physical buyer → AI attach | B10: % | C10: 0.07 | D10: 0.1 | E10: 0.15 | F10: =IF($B$5="Downside",C10,IF($B$5="Upside",E10,D10)) -> 0.1 | G10: Confirmed base hypothesis: AI supports the purchased workbook | H10: Confirmed base
A11: Annual payment share | B11: % | C11: 0.25 | D11: 0.3 | E11: 0.35 | F11: =IF($B$5="Downside",C11,IF($B$5="Upside",E11,D11)) -> 0.3 | G11: Confirmed mix: 30% annual / 70% monthly | H11: Confirmed base
A12: Monthly AI churn | B12: % | C12: 0.1 | D12: 0.08 | E12: 0.05 | F12: =IF($B$5="Downside",C12,IF($B$5="Upside",E12,D12)) -> 0.08 | G12: Base from reconciled AI model; 5% is target | H12: Confirmed base
A13: Annual AI renewal rate | B13: % | C13: 0.3 | D13: 0.45 | E13: 0.55 | F13: =IF($B$5="Downside",C13,IF($B$5="Upside",E13,D13)) -> 0.45 | G13: Separate assumption for annual cohorts after 12 months | H13: To validate
A14: Physical repeat / cross-sell after 12m | B14: % | C14: 0.0893 | D14: 0.1 | E14: 0.15 | F14: =IF($B$5="Downside",C14,IF($B$5="Upside",E14,D14)) -> 0.1 | G14: Historical repeat rate since 2023: 8.93%; base rounded to 10% | H14: Confirmed base
A15: Physical paid CAC per order | B15: € | C15: 16 | D15: 11.5 | E15: 9.7 | F15: =IF($B$5="Downside",C15,IF($B$5="Upside",E15,D15)) -> 11.5 | G15: Base target near 2023 ADV/order (€9.67), with execution buffer | H15: Core recovery gate
A16: Direct AI blended CAC — Test | B16: € | C16: 30 | D16: 22.4 | E16: 15 | F16: =IF($B$5="Downside",C16,IF($B$5="Upside",E16,D16)) -> 22.4 | G16: 80% paid at €28 in base ⇒ blended CAC €22.40 | H16: Working target
A17: Organic physical orders in M1 | B17: orders | C17: 80 | D17: 100 | E17: 120 | F17: =IF($B$5="Downside",C17,IF($B$5="Upside",E17,D17)) -> 100 | G17: Owned demand before paid relaunch | H17: To validate
A18: Monthly physical growth before scale | B18: % | C18: 0 | D18: 0.01 | E18: 0.02 | F18: =IF($B$5="Downside",C18,IF($B$5="Upside",E18,D18)) -> 0.01 | G18: M1–M6, before commercial proof | H18: To validate
A19: Monthly physical growth after scale | B19: % | C19: 0.01 | D19: 0.02 | E19: 0.03 | F19: =IF($B$5="Downside",C19,IF($B$5="Upside",E19,D19)) -> 0.02 | G19: M7 onward, only after recovery gate | H19: To validate
A20: Beta direct AI users / month | B20: users | C20: 30 | D20: 50 | E20: 80 | F20: =IF($B$5="Downside",C20,IF($B$5="Upside",E20,D20)) -> 50 | G20: Owned beta users from launch month through M6 | H20: To validate
... A25: Physical media budget M7–M12 | B25: €/month | C25: 8000 | D25: 11000 | E25: 13000 | F25: =IF($B$5="Downside",C25,IF($B$5="Upside",E25,D25)) -> 11000 | G25: Calibrated to recover approximately the 2023 order volume in Year 1 | H25: To validate
A27: PRICING, UNIT ECONOMICS & OPERATING INPUTS
A28: Input | B28: Unit | C28: Value | D28: Formula / source | H28: Status
A29: AI monthly price | B29: €/month | C29: 9 | D29: Management confirmed — August 2026 | H29: Confirmed
A30: AI annual standard price | B30: €/year | C30: 89 | D30: Management confirmed — renewals at standard price | H30: Confirmed
A31: AI annual founding / community price — first year | B31: €/year | C31: 69 | D31: Launch offer for community, historical and workbook-linked users; renews at €89 | H31: Confirmed
A32: VAT | B32: % | C32: 0.22 | D32: Italian consumer pricing assumption | H32: To validate
A33: Payment/platform fees | B33: % revenue net of VAT | C33: 0.15 | D33: Reconciled AI economic model | H33: To validate
A34: API cost per active user | B34: €/month | C34: 0.95 | D34: Reconciled AI economic model | H34: Confirmed model
A35: Cloud cost per active user | B35: €/month | C35: 0.3 | D35: Reconciled AI economic model | H35: Confirmed model
A36: Annual refund reserve | B36: % gross annual price | C36: 0.03 | D36: Reconciled AI economic model | H36: Confirmed model
A37: Monthly AI contribution per active user — €9 | B37: €/month | C37: =C29/(1+C32)*(1-C33)-C34-C35 -> 5.0204918 | D37: Net of VAT, fees, API and cloud | H37: Calculated
A38: Annual AI contribution — €89 | B38: €/sale | C38: =C30/(1+C32)*(1-C33-C36)-12*(C34+C35) -> 44.819672 | D38: Net of VAT, fees/refunds and 12m API/cloud | H38: Calculated
A39: Annual AI contribution — €69 founding | B39: €/sale | C39: =C31/(1+C32)*(1-C33-C36)-12*(C34+C35) -> 31.377049 | D39: Net of VAT, fees/refunds and 12m API/cloud | H39: Calculated
A40: Physical net revenue per order | B40: €/order | C40: 32 | D40: Planning value agreed; retail prices are €32.90 Diario and €34.90 Crea/L'Arte | H40: Confirmed planning value
A41: Print + shipping/stock per order | B41: €/order | C41: 12 | D41: €5 print + ~€7 shipping/stock | H41: Confirmed
A42: Historical customer database | B42: people | C42: 21000 | D42: Management estimate | H42: Confirmed
A43: Historical Diary purchasers | B43: people | C43: 18000 | D43: Management estimate | H43: Confirmed
A44: Physical copies sold historically — all channels | B44: copies | C44: 40000 | D44: Management estimate including ecommerce, Amazon, retail and corporate channels | H44: Confirmed
A45: Legacy physical fixed costs | B45: €/year | C45: 15000 | D45: Excludes founder compensation | H45: Confirmed
A46: Founder compensation | B46: €/year | C46: 0 | D46: Editable; default requested = zero | H46: Confirmed default
...

Sheet Historical Actuals
A1: TUPENSACI | Historical Actuals
A2: Normalized from ANALISI ORDINI TP — sheet ‘Incassato e speso giornaliero’. 2026 is YTD through 17 June.
A4: ACTUAL PERFORMANCE
A5: Period | B5: Revenue | C5: ADV | D5: Print + fulfillment | E5: Fixed costs | F5: Operating result | G5: Fulfilled units | H5: MER | I5: ADV / unit | J5: Note
A6: 2023 | B6: 284492.32 | C6: 103161.38 | D6: 128076 | E6: 15000 | F6: =B6-C6-D6-E6 -> 38254.937 | G6: =D6/12 -> 10673 | H6: =B6/C6 -> 2.7577405 | I6: =C6/G6 -> 9.6656404 | J6: Full year
A7: 2024 | B7: 291924.17 | C7: 135964 | D7: 117804 | E7: 15000 | F7: =B7-C7-D7-E7 -> 23156.172 | G7: =D7/12 -> 9817 | H7: =B7/C7 -> 2.1470696 | I7: =C7/G7 -> 13.849852 | J7: Full year
A8: 2025 | B8: 126066.94 | C8: 84374 | D8: 41052 | E8: 15000 | F8: =B8-C8-D8-E8 -> -14359.056 | G8: =D8/12 -> 3421 | H8: =B8/C8 -> 1.4941445 | I8: =C8/G8 -> 24.663549 | J8: Full year
A9: 2026 YTD | B9: 34032.796 | C9: 25433 | D9: 11064 | E9: 6904.11 | F9: =B9-C9-D9-E9 -> -9368.3137 | G9: =D9/12 -> 922 | H9: =B9/C9 -> 1.3381353 | I9: =C9/G9 -> 27.584599 | J9: To 17 June

Sheet Physical Business
A1: TUPENSACI | Physical Business
A2: Relaunch of Diario, Crea and L’Arte from Month 1: owned demand + performance media + 12-month repeat. The Base case targets a recovery toward the best 2023 commercial KPIs.
A5: Month | B5: M1 | C5: M2 | D5: M3 | E5: M4 | F5: M5 | G5: M6 | H5: M7 | I5: M8 | J5: M9 | K5: M10 | L5: M11 | M5: M12 | N5: M13 | O5: M14 | P5: M15 | Q5: M16 | R5: M17 | S5: M18 | T5: M19 | U5: M20 | V5: M21 | W5: M22 | X5: M23 | Y5: M24 | Z5: M25 | AA5: M26 | AB5: M27 | AC5: M28 | AD5: M29 | AE5: M30 | AF5: M31 | AG5: M32 | AH5: M33 | AI5: M34 | AJ5: M35 | AK5: M36
A6: Year | B6: Y1 | C6: Y1 | D6: Y1 | E6: Y1 | F6: Y1 | G6: Y1 | H6: Y1 | I6: Y1 | J6: Y1 | K6: Y1 | L6: Y1 | M6: Y1 | N6: Y2 | O6: Y2 | P6: Y2 | Q6: Y2 | R6: Y2 | S6: Y2 | T6: Y2 | U6: Y2 | V6: Y2 | W6: Y2 | X6: Y2 | Y6: Y2 | Z6: Y3 | AA6: Y3 | AB6: Y3 | AC6: Y3 | AD6: Y3 | AE6: Y3 | AF6: Y3 | AG6: Y3 | AH6: Y3 | AI6: Y3 | AJ6: Y3 | AK6: Y3
A7: Stage | B7: Relaunch | C7: Relaunch | D7: Relaunch | E7: Beta build | F7: Beta build | G7: Gate M6 | H7: AI launch | I7: AI launch | J7: AI launch | K7: Scale test | L7: Scale test | M7: Scale test | N7: Scale | O7: Scale | P7: Scale | Q7: Scale | R7: Scale | S7: Scale | T7: Scale | U7: Scale | V7: Scale | W7: Scale | X7: Scale | Y7: Scale | Z7: Scale | AA7: Scale | AB7: Scale | AC7: Scale | AD7: Scale | AE7: Scale | AF7: Scale | AG7: Scale | AH7: Scale | AI7: Scale | AJ7: Scale | AK7: Scale
A9: PHYSICAL CUSTOMER & ORDER ENGINE
A10: Organic / owned new orders | B10: =Assumptions!$F$17 -> 100 | C10: =B10*(1+IF(2<10,Assumptions!$F$18,Assumptions!$F$19)) -> 101 | D10: =C10*(1+IF(3<10,Assumptions!$F$18,Assumptions!$F$19)) -> 102.01 | E10: =D10*(1+IF(4<10,Assumptions!$F$18,Assumptions!$F$19)) -> 103.0301 | F10: =E10*(1+IF(5<10,Assumptions!$F$18,Assumptions!$F$19)) -> 104.0604 | G10: =F10*(1+IF(6<10,Assumptions!$F$18,Assumptions!$F$19)) -> 105.10101 | H10: =G10*(1+IF(7<10,Assumptions!$F$18,Assumptions!$F$19)) -> 106.15202 | I10: =H10*(1+IF(8<10,Assumptions!$F$18,Assumptions!$F$19)) -> 107.21354 | J10: =I10*(1+IF(9<10,Assumptions!$F$18,Assumptions!$F$19)) -> 108.28567 | K10: =J10*(1+IF(10<10,Assumptions!$F$18,Assumptions!$F$19)) -> 110.45138 | L10: =K10*(1+IF(11<10,Assumptions!$F$18,Assumptions!$F$19)) -> 112.66041 | M10: =L10*(1+IF(12<10,Assumptions!$F$18,Assumptions!$F$19)) -> 114.91362 | N10: =M10*(1+IF(13<10,Assumptions!$F$18,Assumptions!$F$19)) -> 117.21189 | O10: =N10*(1+IF(14<10,Assumptions!$F$18,Assumptions!$F$19)) -> 119.55613 | P10: =O10*(1+IF(15<10,Assumptions!$F$18,Assumptions!$F$19)) -> 121.94725 | Q10: =P10*(1+IF(16<10,Assumptions!$F$18,Assumptions!$F$19)) -> 124.3862 | R10: =Q10*(1+IF(17<10,Assumptions!$F$18,Assumptions!$F$19)) -> 126.87392 | S10: =R10*(1+IF(18<10,Assumptions!$F$18,Assumptions!$F$19)) -> 129.4114 | T10: =S10*(1+IF(19<10,Assumptions!$F$18,Assumptions!$F$19)) -> 131.99963 | U10: =T10*(1+IF(20<10,Assumptions!$F$18,Assumptions!$F$19)) -> 134.63962 | V10: =U10*(1+IF(21<10,Assumptions!$F$18,Assumptions!$F$19)) -> 137.33241 | W10: =V10*(1+IF(22<10,Assumptions!$F$18,Assumptions!$F$19)) -> 140.07906 | X10: =W10*(1+IF(23<10,Assumptions!$F$18,Assumptions!$F$19)) -> 142.88064 | Y10: =X10*(1+IF(24<10,Assumptions!$F$18,Assumptions!$F$19)) -> 145.73826 | Z10: =Y10*(1+IF(25<10,Assumptions!$F$18,Assumptions!$F$19)) -> 148.65302 | AA10: =Z10*(1+IF(26<10,Assumptions!$F$18,Assumptions!$F$19)) -> 151.62608 | AB10: =AA10*(1+IF(27<10,Assumptions!$F$18,Assumptions!$F$19)) -> 154.6586 | AC10: =AB10*(1+IF(28<10,Assumptions!$F$18,Assumptions!$F$19)) -> 157.75177 | AD10: =AC10*(1+IF(29<10,Assumptions!$F$18,Assumptions!$F$19)) -> 160.90681 | AE10: =AD10*(1+IF(30<10,Assumptions!$F$18,Assumptions!$F$19)) -> 164.12495 | AF10: =AE10*(1+IF(31<10,Assumptions!$F$18,Assumptions!$F$19)) -> 167.40745 | AG10: =AF10*(1+IF(32<10,Assumptions!$F$18,Assumptions!$F$19)) -> 170.75559 | AH10: =AG10*(1+IF(33<10,Assumptions!$F$18,Assumptions!$F$19)) -> 174.17071 | AI10: =AH10*(1+IF(34<10,Assumptions!$F$18,Assumptions!$F$19)) -> 177.65412 | AJ10: =AI10*(1+IF(35<10,Assumptions!$F$18,Assumptions!$F$19)) -> 181.2072 | AK10: =AJ10*(1+IF(36<10,Assumptions!$F$18,Assumptions!$F$19)) -> 184.83135
A11: Paid media budget | B11: =IF(1<4,Assumptions!$F$23,IF(1<7,Assumptions!$F$24,IF(1<13,Assumptions!$F$25,Assumptions!$F$82))) -> 6000 | C11: =IF(2<4,Assumptions!$F$23,IF(2<7,Assumptions!$F$24,IF(2<13,Assumptions!$F$25,Assumptions!$F$82))) -> 6000 | D11: =IF(3<4,Assumptions!$F$23,IF(3<7,Assumptions!$F$24,IF(3<13,Assumptions!$F$25,Assumptions!$F$82))) -> 6000 | E11: =IF(4<4,Assumptions!$F$23,IF(4<7,Assumptions!$F$24,IF(4<13,Assumptions!$F$25,Assumptions!$F$82))) -> 8000 | F11: =IF(5<4,Assumptions!$F$23,IF(5<7,Assumptions!$F$24,IF(5<13,Assumptions!$F$25,Assumptions!$F$82))) -> 8000 | G11: =IF(6<4,Assumptions!$F$23,IF(6<7,Assumptions!$F$24,IF(6<13,Assumptions!$F$25,Assumptions!$F$82))) -> 8000 | H11: =IF(7<4,Assumptions!$F$23,IF(7<7,Assumptions!$F$24,IF(7<13,Assumptions!$F$25,Assumptions!$F$82))) -> 11000 | I11: =IF(8<4,Assumptions!$F$23,IF(8<7,Assumptions!$F$24,IF(8<13,Assumptions!$F$25,Assumptions!$F$82))) -> 11000 | J11: =IF(9<4,Assumptions!$F$23,IF(9<7,Assumptions!$F$24,IF(9<13,Assumptions!$F$25,Assumptions!$F$82))) -> 11000 | K11: =IF(10<4,Assumptions!$F$23,IF(10<7,Assumptions!$F$24,IF(10<13,Assumptions!$F$25,Assumptions!$F$82))) -> 11000 | L11: =IF(11<4,Assumptions!$F$23,IF(11<7,Assumptions!$F$24,IF(11<13,Assumptions!$F$25,Assumptions!$F$82))) -> 11000 | M11: =IF(12<4,Assumptions!$F$23,IF(12<7,Assumptions!$F$24,IF(12<13,Assumptions!$F$25,Assumptions!$F$82))) -> 11000 | N11: =IF(13<4,Assumptions!$F$23,IF(13<7,Assumptions!$F$24,IF(13<13,Assumptions!$F$25,Assumptions!$F$82))) -> 12000 | O11: =IF(14<4,Assumptions!$F$23,IF(14<7,Assumptions!$F$24,IF(14<13,Assumptions!$F$25,Assumptions!$F$82))) -> 12000 | P11: =IF(15<4,Assumptions!$F$23,IF(15<7,Assumptions!$F$24,IF(15<13,Assumptions!$F$25,Assumptions!$F$82))) -> 12000 | Q11: =IF(16<4,Assumptions!$F$23,IF(16<7,Assumptions!$F$24,IF(16<13,Assumptions!$F$25,Assumptions!$F$82))) -> 12000 | R11: =IF(17<4,Assumptions!$F$23,IF(17<7,Assumptions!$F$24,IF(17<13,Assumptions!$F$25,Assumptions!$F$82))) -> 12000 | S11: =IF(18<4,Assumptions!$F$23,IF(18<7,Assumptions!$F$24,IF(18<13,Assumptions!$F$25,Assumptions!$F$82))) -> 12000 | T11: =IF(19<4,Assumptions!$F$23,IF(19<7,Assumptions!$F$24,IF(19<13,Assumptions!$F$25,Assumptions!$F$82))) -> 12000 | U11: =IF(20<4,Assumptions!$F$23,IF(20<7,Assumptions!$F$24,IF(20<13,Assumptions!$F$25,Assumptions!$F$82))) -> 12000 | V11: =IF(21<4,Assumptions!$F$23,IF(21<7,Assumptions!$F$24,IF(21<13,Assumptions!$F$25,Assumptions!$F$82))) -> 12000 | W11: =IF(22<4,Assumptions!$F$23,IF(22<7,Assumptions!$F$24,IF(22<13,Assumptions!$F$25,Assumptions!$F$82))) -> 12000 | X11: =IF(23<4,Assumptions!$F$23,IF(23<7,Assumptions!$F$24,IF(23<13,Assumptions!$F$25,Assumptions!$F$82))) -> 12000 | Y11: =IF(24<4,Assumptions!$F$23,IF(24<7,Assumptions!$F$24,IF(24<13,Assumptions!$F$25,Assumptions!$F$82))) -> 12000 | Z11: =IF(25<4,Assumptions!$F$23,IF(25<7,Assumptions!$F$24,IF(25<13,Assumptions!$F$25,Assumptions!$F$82))) -> 12000 | AA11: =IF(26<4,Assumptions!$F$23,IF(26<7,Assumptions!$F$24,IF(26<13,Assumptions!$F$25,Assumptions!$F$82))) -> 12000 | AB11: =IF(27<4,Assumptions!$F$23,IF(27<7,Assumptions!$F$24,IF(27<13,Assumptions!$F$25,Assumptions!$F$82))) -> 12000 | AC11: =IF(28<4,Assumptions!$F$23,IF(28<7,Assumptions!$F$24,IF(28<13,Assumptions!$F$25,Assumptions!$F$82))) -> 12000 | AD11: =IF(29<4,Assumptions!$F$23,IF(29<7,Assumptions!$F$24,IF(29<13,Assumptions!$F$25,Assumptions!$F$82))) -> 12000 | AE11: =IF(30<4,Assumptions!$F$23,IF(30<7,Assumptions!$F$24,IF(30<13,Assumptions!$F$25,Assumptions!$F$82))) -> 12000 | AF11: =IF(31<4,Assumptions!$F$23,IF(31<7,Assumptions!$F$24,IF(31<13,Assumptions!$F$25,Assumptions!$F$82))) -> 12000 | AG11: =IF(32<4,Assumptions!$F$23,IF(32<7,Assumptions!$F$24,IF(32<13,Assumptions!$F$25,Assumptions!$F$82))) -> 12000 | AH11: =IF(33<4,Assumptions!$F$23,IF(33<7,Assumptions!$F$24,IF(33<13,Assumptions!$F$25,Assumptions!$F$82))) -> 12000 | AI11: =IF(34<4,Assumptions!$F$23,IF(34<7,Assumptions!$F$24,IF(34<13,Assumptions!$F$25,Assumptions!$F$82))) -> 12000 | AJ11: =IF(35<4,Assumptions!$F$23,IF(35<7,Assumptions!$F$24,IF(35<13,Assumptions!$F$25,Assumptions!$F$82))) -> 12000 | AK11: =IF(36<4,Assumptions!$F$23,IF(36<7,Assumptions!$F$24,IF(36<13,Assumptions!$F$25,Assumptions!$F$82))) -> 12000
A12: Paid-acquired new orders | B12: =B11/Assumptions!$F$15 -> 521.73913 | C12: =C11/Assumptions!$F$15 -> 521.73913 | D12: =D11/Assumptions!$F$15 -> 521.73913 | E12: =E11/Assumptions!$F$15 -> 695.65217 | F12: =F11/Assumptions!$F$15 -> 695.65217 | G12: =G11/Assumptions!$F$15 -> 695.65217 | H12: =H11/Assumptions!$F$15 -> 956.52174 | I12: =I11/Assumptions!$F$15 -> 956.52174 | ... AK12: =AK11/Assumptions!$F$15 -> 1043.4783
A13: Repeat / cross-sell orders (12m lag) | B13: 0 | C13: 0 | D13: 0 | E13: 0 | F13: 0 | G13: 0 | H13: 0 | I13: 0 | J13: 0 | K13: 0 | L13: 0 | M13: 0 | N13: =B15*Assumptions!$F$14 -> 62.173913 | O13: =C15*Assumptions!$F$14 -> 62.273913 | P13: =D15*Assumptions!$F$14 -> 62.374913 | Q13: =E15*Assumptions!$F$14 -> 79.868227 | R13: =F15*Assumptions!$F$14 -> 79.971257 | S13: =G15*Assumptions!$F$14 -> 80.075318 | T13: =H15*Assumptions!$F$14 -> 106.26738 | U13: =I15*Assumptions!$F$14 -> 106.37353 | ... AK13: =Y15*Assumptions!$F$14 -> 118.92165
A14: Total physical orders | B14: =SUM(B10,B12,B13) -> 621.73913 | C14: =SUM(C10,C12,C13) -> 622.73913 | D14: =SUM(D10,D12,D13) -> 623.74913 | E14: =SUM(E10,E12,E13) -> 798.68227 | F14: =SUM(F10,F12,F13) -> 799.71257 | G14: =SUM(G10,G12,G13) -> 800.75318 | H14: =SUM(H10,H12,H13) -> 1062.6738 | I14: =SUM(I10,I12,I13) -> 1063.7353 | ... AK14: =SUM(AK10,AK12,AK13) -> 1347.2313
A15: New unique physical buyers | B15: =SUM(B10,B12) -> 621.73913 | C15: =SUM(C10,C12) -> 622.73913 | D15: =SUM(D10,D12) -> 623.74913 | E15: =SUM(E10,E12) -> 798.68227 | F15: =SUM(F10,F12) -> 799.71257 | G15: =SUM(G10,G12) -> 800.75318 | H15: =SUM(H10,H12) -> 1062.6738 | I15: =SUM(I10,I12) -> 1063.7353 | ... AK15: =SUM(AK10,AK12) -> 1228.3096
A16: Cumulative addressable physical database | B16: =Assumptions!$C$42+B15 -> 21621.739 | C16: =B16+C15 -> 22244.478 | D16: =C16+D15 -> 22868.227 | E16: =D16+E15 -> 23666.91 | F16: =E16+F15 -> 24466.622 | G16: =F16+G15 -> 25267.375 | H16: =G16+H15 -> 26330.049 | I16: =H16+I15 -> 27393.784 | J16: =I16+J15 -> 28458.592 | ... AK16: =AJ16+AK15 -> 60275.465
A18: Net physical revenue | B18: =B14*Assumptions!$C$40 -> 19895.652 | C18: =C14*Assumptions!$C$40 -> 19927.652 | D18: =D14*Assumptions!$C$40 -> 19959.972 | E18: =E14*Assumptions!$C$40 -> 25557.833 | F18: =F14*Assumptions!$C$40 -> 25590.802 | G18: =G14*Assumptions!$C$40 -> 25624.102 | H18: =H14*Assumptions!$C$40 -> 34005.56 | I18: =I14*Assumptions!$C$40 -> 34039.529 | ... AK18: =AK14*Assumptions!$C$40 -> 43111.4
A19: Print + fulfillment cost | B19: =-B14*Assumptions!$C$41 -> -7460.8696 | C19: =-C14*Assumptions!$C$41 -> -7472.8696 | D19: =-D14*Assumptions!$C$41 -> -7484.9896 | E19: =-E14*Assumptions!$C$41 -> -9584.1873 | F19: =-F14*Assumptions!$C$41 -> -9596.5509 | G19: =-G14*Assumptions!$C$41 -> -9609.0381 | H19: =-H14*Assumptions!$C$41 -> -12752.085 | I19: =-I14*Assumptions!$C$41 -> -12764.823 | ... AK19: =-AK14*Assumptions!$C$41 -> -16166.775
A20: Physical acquisition cost | B20: =-B11 -> -6000 | C20: =-C11 -> -6000 | D20: =-D11 -> -6000 | E20: =-E11 -> -8000 | F20: =-F11 -> -8000 | G20: =-G11 -> -8000 | H20: =-H11 -> -11000 | I20: =-I11 -> -11000 | ... AK20: =-AK11 -> -12000
A21: Physical contribution after acquisition | B21: =SUM(B18:B20) -> 6434.7826 | C21: =SUM(C18:C20) -> 6454.7826 | D21: =SUM(D18:D20) -> 6474.9826 | E21: =SUM(E18:E20) -> 7973.6455 | F21: =SUM(F18:F20) -> 7994.2515 | G21: =SUM(G18:G20) -> 8015.0636 | H21: =SUM(H18:H20) -> 10253.475 | I21: =SUM(I18:I20) -> 10274.705 | ... AK21: =SUM(AK18:AK20) -> 14944.625
A23: AI attached users from physical buyers | B23: =B15*Assumptions!$F$10 -> 62.173913 | C23: =C15*Assumptions!$F$10 -> 62.273913 | D23: =D15*Assumptions!$F$10 -> 62.374913 | E23: =E15*Assumptions!$F$10 -> 79.868227 | F23: =F15*Assumptions!$F$10 -> 79.971257 | G23: =G15*Assumptions!$F$10 -> 80.075318 | H23: =H15*Assumptions!$F$10 -> 106.26738 | I23: =I15*Assumptions!$F$10 -> 106.37353 | ... AK23: =AK15*Assumptions!$F$10 -> 122.83096

Sheet AI Cohorts
A1: TUPENSACI | AI Cohorts — Base Case v3.0
A2: Il Base mantiene i volumi di acquisizione della v2.1 e cambia soltanto pricing e margine: €9/mese, €89/anno, €69 founding per community/clienti nel primo anno. La prova guidata dura 7 giorni e non è un tier gratuito permanente.
A5: Month | B5: M1 | C5: M2 | D5: M3 | E5: M4 | F5: M5 | G5: M6 | H5: M7 | I5: M8 | J5: M9 | K5: M10 | L5: M11 | M5: M12 | N5: M13 | O5: M14 | P5: M15 | Q5: M16 | R5: M17 | S5: M18 | T5: M19 | U5: M20 | V5: M21 | W5: M22 | X5: M23 | Y5: M24 | Z5: M25 | AA5: M26 | AB5: M27 | AC5: M28 | AD5: M29 | AE5: M30 | AF5: M31 | AG5: M32 | AH5: M33 | AI5: M34 | AJ5: M35 | AK5: M36
A6: Year | B6: Y1 | C6: Y1 | D6: Y1 | E6: Y1 | F6: Y1 | G6: Y1 | H6: Y1 | I6: Y1 | J6: Y1 | K6: Y1 | L6: Y1 | M6: Y1 | N6: Y2 | O6: Y2 | P6: Y2 | Q6: Y2 | R6: Y2 | S6: Y2 | T6: Y2 | U6: Y2 | V6: Y2 | W6: Y2 | X6: Y2 | Y6: Y2 | Z6: Y3 | AA6: Y3 | AB6: Y3 | AC6: Y3 | AD6: Y3 | AE6: Y3 | AF6: Y3 | AG6: Y3 | AH6: Y3 | AI6: Y3 | AJ6: Y3 | AK6: Y3
A7: Stage | B7: Relaunch | C7: Relaunch | D7: Relaunch | E7: Beta build | F7: Beta build | G7: Gate M6 | H7: AI launch | I7: AI launch | J7: AI launch | K7: Scale test | L7: Scale test | M7: Scale test | N7: Scale | O7: Scale | P7: Scale | Q7: Scale | R7: Scale | S7: Scale | T7: Scale | U7: Scale | V7: Scale | W7: Scale | X7: Scale | Y7: Scale | Z7: Scale | AA7: Scale | AB7: Scale | AC7: Scale | AD7: Scale | AE7: Scale | AF7: Scale | AG7: Scale | AH7: Scale | AI7: Scale | AJ7: Scale | AK7: Scale
A9: AI ACQUISITION & COHORT ROLL-FORWARD
A10: Historical database conversions | B10: =IF(AND(1>=Assumptions!$C$49,1<Assumptions!$C$49+Assumptions!$C$52),Assumptions!$C$42*Assumptions!$F$9/Assumptions!$C$52,0) -> 0 | C10: =IF(AND(2>=Assumptions!$C$49,2<Assumptions!$C$49+Assumptions!$C$52),Assumptions!$C$42*Assumptions!$F$9/Assumptions!$C$52,0) -> 0 | D10: =IF(AND(3>=Assumptions!$C$49,3<Assumptions!$C$49+Assumptions!$C$52),Assumptions!$C$42*Assumptions!$F$9/Assumptions!$C$52,0) -> 0 | E10: =IF(AND(4>=Assumptions!$C$49,4<Assumptions!$C$49+Assumptions!$C$52),Assumptions!$C$42*Assumptions!$F$9/Assumptions!$C$52,0) -> 70 | F10: =IF(AND(5>=Assumptions!$C$49,5<Assumptions!$C$49+Assumptions!$C$52),Assumptions!$C$42*Assumptions!$F$9/Assumptions!$C$52,0) -> 70 | G10: =IF(AND(6>=Assumptions!$C$49,6<Assumptions!$C$49+Assumptions!$C$52),Assumptions!$C$42*Assumptions!$F$9/Assumptions!$C$52,0) -> 70 | H10: =IF(AND(7>=Assumptions!$C$49,7<Assumptions!$C$49+Assumptions!$C$52),Assumptions!$C$42*Assumptions!$F$9/Assumptions!$C$52,0) -> 70 | I10: =IF(AND(8>=Assumptions!$C$49,8<Assumptions!$C$49+Assumptions!$C$52),Assumptions!$C$42*Assumptions!$F$9/Assumptions!$C$52,0) -> 70 | J10: =IF(AND(9>=Assumptions!$C$49,9<Assumptions!$C$49+Assumptions!$C$52),Assumptions!$C$42*Assumptions!$F$9/Assumptions!$C$52,0) -> 70 | K10: =IF(AND(10>=Assumptions!$C$49,10<Assumptions!$C$49+Assumptions!$C$52),Assumptions!$C$42*Assumptions!$F$9/Assumptions!$C$52,0) -> 0 | L10: =IF(AND(11>=Assumptions!$C$49,11<Assumptions!$C$49+Assumptions!$C$52),Assumptions!$C$42*Assumptions!$F$9/Assumptions!$C$52,0) -> 0 | M10: =IF(AND(12>=Assumptions!$C$49,12<Assumptions!$C$49+Assumptions!$C$52),Assumptions!$C$42*Assumptions!$F$9/Assumptions!$C$52,0) -> 0 | N10: =IF(AND(13>=Assumptions!$C$49,13<Assumptions!$C$49+Assumptions!$C$52),Assumptions!$C$42*Assumptions!$F$9/Assumptions!$C$52,0) -> 0 | O10: =IF(AND(14>=Assumptions!$C$49,14<Assumptions!$C$49+Assumptions!$C$52),Assumptions!$C$42*Assumptions!$F$9/Assumptions!$C$52,0) -> 0 | P10: =IF(AND(15>=Assumptions!$C$49,15<Assumptions!$C$49+Assumptions!$C$52),Assumptions!$C$42*Assumptions!$F$9/Assumptions!$C$52,0) -> 0 | Q10: =IF(AND(16>=Assumptions!$C$49,16<Assumptions!$C$49+Assumptions!$C$52),Assumptions!$C$42*Assumptions!$F$9/Assumptions!$C$52,0) -> 0 | R10: =IF(AND(17>=Assumptions!$C$49,17<Assumptions!$C$49+Assumptions!$C$52),Assumptions!$C$42*Assumptions!$F$9/Assumptions!$C$52,0) -> 0 | S10: =IF(AND(18>=Assumptions!$C$49,18<Assumptions!$C$49+Assumptions!$C$52),Assumptions!$C$42*Assumptions!$F$9/Assumptions!$C$52,0) -> 0 | T10: =IF(AND(19>=Assumptions!$C$49,19<Assumptions!$C$49+Assumptions!$C$52),Assumptions!$C$42*Assumptions!$F$9/Assumptions!$C$52,0) -> 0 | U10: =IF(AND(20>=Assumptions!$C$49,20<Assumptions!$C$49+Assumptions!$C$52),Assumptions!$C$42*Assumptions!$F$9/Assumptions!$C$52,0) -> 0 | V10: =IF(AND(21>=Assumptions!$C$49,21<Assumptions!$C$49+Assumptions!$C$52),Assumptions!$C$42*Assumptions!$F$9/Assumptions!$C$52,0) -> 0 | W10: =IF(AND(22>=Assumptions!$C$49,22<Assumptions!$C$49+Assumptions!$C$52),Assumptions!$C$42*Assumptions!$F$9/Assumptions!$C$52,0) -> 0 | X10: =IF(AND(23>=Assumptions!$C$49,23<Assumptions!$C$49+Assumptions!$C$52),Assumptions!$C$42*Assumptions!$F$9/Assumptions!$C$52,0) -> 0 | Y10: =IF(AND(24>=Assumptions!$C$49,24<Assumptions!$C$49+Assumptions!$C$52),Assumptions!$C$42*Assumptions!$F$9/Assumptions!$C$52,0) -> 0 | Z10: =IF(AND(25>=Assumptions!$C$49,25<Assumptions!$C$49+Assumptions!$C$52),Assumptions!$C$42*Assumptions!$F$9/Assumptions!$C$52,0) -> 0 | AA10: =IF(AND(26>=Assumptions!$C$49,26<Assumptions!$C$49+Assumptions!$C$52),Assumptions!$C$42*Assumptions!$F$9/Assumptions!$C$52,0) -> 0 | AB10: =IF(AND(27>=Assumptions!$C$49,27<Assumptions!$C$49+Assumptions!$C$52),Assumptions!$C$42*Assumptions!$F$9/Assumptions!$C$52,0) -> 0 | AC10: =IF(AND(28>=Assumptions!$C$49,28<Assumptions!$C$49+Assumptions!$C$52),Assumptions!$C$42*Assumptions!$F$9/Assumptions!$C$52,0) -> 0 | AD10: =IF(AND(29>=Assumptions!$C$49,29<Assumptions!$C$49+Assumptions!$C$52),Assumptions!$C$42*Assumptions!$F$9/Assumptions!$C$52,0) -> 0 | AE10: =IF(AND(30>=Assumptions!$C$49,30<Assumptions!$C$49+Assumptions!$C$52),Assumptions!$C$42*Assumptions!$F$9/Assumptions!$C$52,0) -> 0 | AF10: =IF(AND(31>=Assumptions!$C$49,31<Assumptions!$C$49+Assumptions!$C$52),Assumptions!$C$42*Assumptions!$F$9/Assumptions!$C$52,0) -> 0 | AG10: =IF(AND(32>=Assumptions!$C$49,32<Assumptions!$C$49+Assumptions!$C$52),Assumptions!$C$42*Assumptions!$F$9/Assumptions!$C$52,0) -> 0 | AH10: =IF(AND(33>=Assumptions!$C$49,33<Assumptions!$C$49+Assumptions!$C$52),Assumptions!$C$42*Assumptions!$F$9/Assumptions!$C$52,0) -> 0 | AI10: =IF(AND(34>=Assumptions!$C$49,34<Assumptions!$C$49+Assumptions!$C$52),Assumptions!$C$42*Assumptions!$F$9/Assumptions!$C$52,0) -> 0 | AJ10: =IF(AND(35>=Assumptions!$C$49,35<Assumptions!$C$49+Assumptions!$C$52),Assumptions!$C$42*Assumptions!$F$9/Assumptions!$C$52,0) -> 0 | AK10: =IF(AND(36>=Assumptions!$C$49,36<Assumptions!$C$49+Assumptions!$C$52),Assumptions!$C$42*Assumptions!$F$9/Assumptions!$C$52,0) -> 0
A11: Physical buyer AI attach conversions | B11: =IF(1<Assumptions!$C$49,0,'Physical Business'!B23) -> 0 | C11: =IF(2<Assumptions!$C$49,0,'Physical Business'!C23) -> 0 | D11: =IF(3<Assumptions!$C$49,0,'Physical Business'!D23) -> 0 | E11: =IF(4<Assumptions!$C$49,0,'Physical Business'!E23) -> 79.868227 | F11: =IF(5<Assumptions!$C$49,0,'Physical Business'!F23) -> 79.971257 | G11: =IF(6<Assumptions!$C$49,0,'Physical Business'!G23) -> 80.075318 | H11: =IF(7<Assumptions!$C$49,0,'Physical Business'!H23) -> 106.26738 | I11: =IF(8<Assumptions!$C$49,0,'Physical Business'!I23) -> 106.37353 | J11: =IF(9<Assumptions!$C$49,0,'Physical Business'!J23) -> 106.48074 | K11: =IF(10<Assumptions!$C$49,0,'Physical Business'!K23) -> 106.69731 | L11: =IF(11<Assumptions!$C$49,0,'Physical Business'!L23) -> 106.91822 | M11: =IF(12<Assumptions!$C$49,0,'Physical Business'!M23) -> 107.14354 | N11: =IF(13<Assumptions!$C$49,0,'Physical Business'!N23) -> 116.06902 | O11: =IF(14<Assumptions!$C$49,0,'Physical Business'!O23) -> 116.30344 | P11: =IF(15<Assumptions!$C$49,0,'Physical Business'!P23) -> 116.54255 | Q11: =IF(16<Assumptions!$C$49,0,'Physical Business'!Q23) -> 116.78645 | R11: =IF(17<Assumptions!$C$49,0,'Physical Business'!R23) -> 117.03522 | S11: =IF(18<Assumptions!$C$49,0,'Physical Business'!S23) -> 117.28897 | T11: =IF(19<Assumptions!$C$49,0,'Physical Business'!T23) -> 117.54779 | U11: =IF(20<Assumptions!$C$49,0,'Physical Business'!U23) -> 117.81179 | V11: =IF(21<Assumptions!$C$49,0,'Physical Business'!V23) -> 118.08107 | W11: =IF(22<Assumptions!$C$49,0,'Physical Business'!W23) -> 118.35573 | X11: =IF(23<Assumptions!$C$49,0,'Physical Business'!X23) -> 118.63589 | Y11: =IF(24<Assumptions!$C$49,0,'Physical Business'!Y23) -> 118.92165 | Z11: =IF(25<Assumptions!$C$49,0,'Physical Business'!Z23) -> 119.21313 | AA11: =IF(26<Assumptions!$C$49,0,'Physical Business'!AA23) -> 119.51043 | AB11: =IF(27<Assumptions!$C$49,0,'Physical Business'!AB23) -> 119.81369 | AC11: =IF(28<Assumptions!$C$49,0,'Physical Business'!AC23) -> 120.123 | AD11: =IF(29<Assumptions!$C$49,0,'Physical Business'!AD23) -> 120.43851 | AE11: =IF(30<Assumptions!$C$49,0,'Physical Business'!AE23) -> 120.76032 | AF11: =IF(31<Assumptions!$C$49,0,'Physical Business'!AF23) -> 121.08857 | AG11: =IF(32<Assumptions!$C$49,0,'Physical Business'!AG23) -> 121.42339 | AH11: =IF(33<Assumptions!$C$49,0,'Physical Business'!AH23) -> 121.7649 | AI11: =IF(34<Assumptions!$C$49,0,'Physical Business'!AI23) -> 122.11324 | AJ11: =IF(35<Assumptions!$C$49,0,'Physical Business'!AJ23) -> 122.46855 | AK11: =IF(36<Assumptions!$C$49,0,'Physical Business'!AK23) -> 122.83096
A12: Owned beta/direct users | B12: =IF(AND(1>=Assumptions!$C$49,1<=Assumptions!$C$50),Assumptions!$F$20,0) -> 0 | C12: =IF(AND(2>=Assumptions!$C$49,2<=Assumptions!$C$50),Assumptions!$F$20,0) -> 0 | D12: =IF(AND(3>=Assumptions!$C$49,3<=Assumptions!$C$50),Assumptions!$F$20,0) -> 0 | E12: =IF(AND(4>=Assumptions!$C$49,4<=Assumptions!$C$50),Assumptions!$F$20,0) -> 50 | F12: =IF(AND(5>=Assumptions!$C$49,5<=Assumptions!$C$50),Assumptions!$F$20,0) -> 50 | G12: =IF(AND(6>=Assumptions!$C$49,6<=Assumptions!$C$50),Assumptions!$F$20,0) -> 50 | H12: =IF(AND(7>=Assumptions!$C$49,7<=Assumptions!$C$50),Assumptions!$F$20,0) -> 0 | I12: =IF(AND(8>=Assumptions!$C$49,8<=Assumptions!$C$50),Assumptions!$F$20,0) -> 0 | J12: =IF(AND(9>=Assumptions!$C$49,9<=Assumptions!$C$50),Assumptions!$F$20,0) -> 0 | K12: =IF(AND(10>=Assumptions!$C$49,10<=Assumptions!$C$50),Assumptions!$F$20,0) -> 0 | L12: =IF(AND(11>=Assumptions!$C$49,11<=Assumptions!$C$50),Assumptions!$F$20,0) -> 0 | M12: =IF(AND(12>=Assumptions!$C$49,12<=Assumptions!$C$50),Assumptions!$F$20,0) -> 0 | N12: =IF(AND(13>=Assumptions!$C$49,13<=Assumptions!$C$50),Assumptions!$F$20,0) -> 0 | O12: =IF(AND(14>=Assumptions!$C$49,14<=Assumptions!$C$50),Assumptions!$F$20,0) -> 0 | P12: =IF(AND(15>=Assumptions!$C$49,15<=Assumptions!$C$50),Assumptions!$F$20,0) -> 0 | Q12: =IF(AND(16>=Assumptions!$C$49,16<=Assumptions!$C$50),Assumptions!$F$20,0) -> 0 | R12: =IF(AND(17>=Assumptions!$C$49,17<=Assumptions!$C$50),Assumptions!$F$20,0) -> 0 | S12: =IF(AND(18>=Assumptions!$C$49,18<=Assumptions!$C$50),Assumptions!$F$20,0) -> 0 | T12: =IF(AND(19>=Assumptions!$C$49,19<=Assumptions!$C$50),Assumptions!$F$20,0) -> 0 | U12: =IF(AND(20>=Assumptions!$C$49,20<=Assumptions!$C$50),Assumptions!$F$20,0) -> 0 | V12: =IF(AND(21>=Assumptions!$C$49,21<=Assumptions!$C$50),Assumptions!$F$20,0) -> 0 | W12: =IF(AND(22>=Assumptions!$C$49,22<=Assumptions!$C$50),Assumptions!$F$20,0) -> 0 | X12: =IF(AND(23>=Assumptions!$C$49,23<=Assumptions!$C$50),Assumptions!$F$20,0) -> 0 | Y12: =IF(AND(24>=Assumptions!$C$49,24<=Assumptions!$C$50),Assumptions!$F$20,0) -> 0 | Z12: =IF(AND(25>=Assumptions!$C$49,25<=Assumptions!$C$50),Assumptions!$F$20,0) -> 0 | AA12: =IF(AND(26>=Assumptions!$C$49,26<=Assumptions!$C$50),Assumptions!$F$20,0) -> 0 | AB12: =IF(AND(27>=Assumptions!$C$49,27<=Assumptions!$C$50),Assumptions!$F$20,0) -> 0 | AC12: =IF(AND(28>=Assumptions!$C$49,28<=Assumptions!$C$50),Assumptions!$F$20,0) -> 0 | AD12: =IF(AND(29>=Assumptions!$C$49,29<=Assumptions!$C$50),Assumptions!$F$20,0) -> 0 | AE12: =IF(AND(30>=Assumptions!$C$49,30<=Assumptions!$C$50),Assumptions!$F$20,0) -> 0 | AF12: =IF(AND(31>=Assumptions!$C$49,31<=Assumptions!$C$50),Assumptions!$F$20,0) -> 0 | AG12: =IF(AND(32>=Assumptions!$C$49,32<=Assumptions!$C$50),Assumptions!$F$20,0) -> 0 | AH12: =IF(AND(33>=Assumptions!$C$49,33<=Assumptions!$C$50),Assumptions!$F$20,0) -> 0 | AI12: =IF(AND(34>=Assumptions!$C$49,34<=Assumptions!$C$50),Assumptions!$F$20,0) -> 0 | AJ12: =IF(AND(35>=Assumptions!$C$49,35<=Assumptions!$C$50),Assumptions!$F$20,0) -> 0 | AK12: =IF(AND(36>=Assumptions!$C$49,36<=Assumptions!$C$50),Assumptions!$F$20,0) -> 0
A13: Direct AI media budget | B13: =IF(1<Assumptions!$C$51,0,IF(Assumptions!$E$5="Test",IF(1<19,Assumptions!$C$64,Assumptions!$C$65),IF(1<19,Assumptions!$F$21,Assumptions!$F$22))) -> 0 | C13: =IF(2<Assumptions!$C$51,0,IF(Assumptions!$E$5="Test",IF(2<19,Assumptions!$C$64,Assumptions!$C$65),IF(2<19,Assumptions!$F$21,Assumptions!$F$22))) -> 0 | D13: =IF(3<Assumptions!$C$51,0,IF(Assumptions!$E$5="Test",IF(3<19,Assumptions!$C$64,Assumptions!$C$65),IF(3<19,Assumptions!$F$21,Assumptions!$F$22))) -> 0 | E13: =IF(4<Assumptions!$C$51,0,IF(Assumptions!$E$5="Test",IF(4<19,Assumptions!$C$64,Assumptions!$C$65),IF(4<19,Assumptions!$F$21,Assumptions!$F$22))) -> 0 | F13: =IF(5<Assumptions!$C$51,0,IF(Assumptions!$E$5="Test",IF(5<19,Assumptions!$C$64,Assumptions!$C$65),IF(5<19,Assumptions!$F$21,Assumptions!$F$22))) -> 0 | G13: =IF(6<Assumptions!$C$51,0,IF(Assumptions!$E$5="Test",IF(6<19,Assumptions!$C$64,Assumptions!$C$65),IF(6<19,Assumptions!$F$21,Assumptions!$F$22))) -> 0 | H13: =IF(7<Assumptions!$C$51,0,IF(Assumptions!$E$5="Test",IF(7<19,Assumptions!$C$64,Assumptions!$C$65),IF(7<19,Assumptions!$F$21,Assumptions!$F$22))) -> 4000 | I13: =IF(8<Assumptions!$C$51,0,IF(Assumptions!$E$5="Test",IF(8<19,Assumptions!$C$64,Assumptions!$C$65),IF(8<19,Assumptions!$F$21,Assumptions!$F$22))) -> 4000 | J13: =IF(9<Assumptions!$C$51,0,IF(Assumptions!$E$5="Test",IF(9<19,Assumptions!$C$64,Assumptions!$C$65),IF(9<19,Assumptions!$F$21,Assumptions!$F$22))) -> 4000 | K13: =IF(10<Assumptions!$C$51,0,IF(Assumptions!$E$5="Test",IF(10<19,Assumptions!$C$64,Assumptions!$C$65),IF(10<19,Assumptions!$F$21,Assumptions!$F$22))) -> 4000 | L13: =IF(11<Assumptions!$C$51,0,IF(Assumptions!$E$5="Test",IF(11<19,Assumptions!$C$64,Assumptions!$C$65),IF(11<19,Assumptions!$F$21,Assumptions!$F$22))) -> 4000 | M13: =IF(12<Assumptions!$C$51,0,IF(Assumptions!$E$5="Test",IF(12<19,Assumptions!$C$64,Assumptions!$C$65),IF(12<19,Assumptions!$F$21,Assumptions!$F$22))) -> 4000 | N13: =IF(13<Assumptions!$C$51,0,IF(Assumptions!$E$5="Test",IF(13<19,Assumptions!$C$64,Assumptions!$C$65),IF(13<19,Assumptions!$F$21,Assumptions!$F$22))) -> 4000 | O13: =IF(14<Assumptions!$C$51,0,IF(Assumptions!$E$5="Test",IF(14<19,Assumptions!$C$64,Assumptions!$C$65),IF(14<19,Assumptions!$F$21,Assumptions!$F$22))) -> 4000 | P13: =IF(15<Assumptions!$C$51,0,IF(Assumptions!$E$5="Test",IF(15<19,Assumptions!$C$64,Assumptions!$C$65),IF(15<19,Assumptions!$F$21,Assumptions!$F$22))) -> 4000 | Q13: =IF(16<Assumptions!$C$51,0,IF(Assumptions!$E$5="Test",IF(16<19,Assumptions!$C$64,Assumptions!$C$65),IF(16<19,Assumptions!$F$21,Assumptions!$F$22))) -> 4000 | R13: =IF(17<Assumptions!$C$51,0,IF(Assumptions!$E$5="Test",IF(17<19,Assumptions!$C$64,Assumptions!$C$65),IF(17<19,Assumptions!$F$21,Assumptions!$F$22))) -> 4000 | S13: =IF(18<Assumptions!$C$51,0,IF(Assumptions!$E$5="Test",IF(18<19,Assumptions!$C$64,Assumptions!$C$65),IF(18<19,Assumptions!$F$21,Assumptions!$F$22))) -> 4000 | T13: =IF(19<Assumptions!$C$51,0,IF(Assumptions!$E$5="Test",IF(19<19,Assumptions!$C$64,Assumptions!$C$65),IF(19<19,Assumptions!$F$21,Assumptions!$F$22))) -> 6000 | U13: =IF(20<Assumptions!$C$51,0,IF(Assumptions!$E$5="Test",IF(20<19,Assumptions!$C$64,Assumptions!$C$65),IF(20<19,Assumptions!$F$21,Assumptions!$F$22))) -> 6000 | V13: =IF(21<Assumptions!$C$51,0,IF(Assumptions!$E$5="Test",IF(21<19,Assumptions!$C$64,Assumptions!$C$65),IF(21<19,Assumptions!$F$21,Assumptions!$F$22))) -> 6000 | W13: =IF(22<Assumptions!$C$51,0,IF(Assumptions!$E$5="Test",IF(22<19,Assumptions!$C$64,Assumptions!$C$65),IF(22<19,Assumptions!$F$21,Assumptions!$F$22))) -> 6000 | X13: =IF(23<Assumptions!$C$51,0,IF(Assumptions!$E$5="Test",IF(23<19,Assumptions!$C$64,Assumptions!$C$65),IF(23<19,Assumptions!$F$21,Assumptions!$F$22))) -> 6000 | Y13: =IF(24<Assumptions!$C$51,0,IF(Assumptions!$E$5="Test",IF(24<19,Assumptions!$C$64,Assumptions!$C$65),IF(24<19,Assumptions!$F$21,Assumptions!$F$22))) -> 6000 | Z13: =IF(25<Assumptions!$C$51,0,IF(Assumptions!$E$5="Test",IF(25<19,Assumptions!$C$64,Assumptions!$C$65),IF(25<19,Assumptions!$F$21,Assumptions!$F$22))) -> 6000 | AA13: =IF(26<Assumptions!$C$51,0,IF(Assumptions!$E$5="Test",IF(26<19,Assumptions!$C$64,Assumptions!$C$65),IF(26<19,Assumptions!$F$21,Assumptions!$F$22))) -> 6000 | AB13: =IF(27<Assumptions!$C$51,0,IF(Assumptions!$E$5="Test",IF(27<19,Assumptions!$C$64,Assumptions!$C$65),IF(27<19,Assumptions!$F$21,Assumptions!$F$22))) -> 6000 | AC13: =IF(28<Assumptions!$C$51,0,IF(Assumptions!$E$5="Test",IF(28<19,Assumptions!$C$64,Assumptions!$C$65),IF(28<19,Assumptions!$F$21,Assumptions!$F$22))) -> 6000 | AD13: =IF(29<Assumptions!$C$51,0,IF(Assumptions!$E$5="Test",IF(29<19,Assumptions!$C$64,Assumptions!$C$65),IF(29<19,Assumptions!$F$21,Assumptions!$F$22))) -> 6000 | AE13: =IF(30<Assumptions!$C$51,0,IF(Assumptions!$E$5="Test",IF(30<19,Assumptions!$C$64,Assumptions!$C$65),IF(30<19,Assumptions!$F$21,Assumptions!$F$22))) -> 6000 | AF13: =IF(31<Assumptions!$C$51,0,IF(Assumptions!$E$5="Test",IF(31<19,Assumptions!$C$64,Assumptions!$C$65),IF(31<19,Assumptions!$F$21,Assumptions!$F$22))) -> 6000 | AG13: =IF(32<Assumptions!$C$51,0,IF(Assumptions!$E$5="Test",IF(32<19,Assumptions!$C$64,Assumptions!$C$65),IF(32<19,Assumptions!$F$21,Assumptions!$F$22))) -> 6000 | AH13: =IF(33<Assumptions!$C$51,0,IF(Assumptions!$E$5="Test",IF(33<19,Assumptions!$C$64,Assumptions!$C$65),IF(33<19,Assumptions!$F$21,Assumptions!$F$22))) -> 6000 | AI13: =IF(34<Assumptions!$C$51,0,IF(Assumptions!$E$5="Test",IF(34<19,Assumptions!$C$64,Assumptions!$C$65),IF(34<19,Assumptions!$F$21,Assumptions!$F$22))) -> 6000 | AJ13: =IF(35<Assumptions!$C$51,0,IF(Assumptions!$E$5="Test",IF(35<19,Assumptions!$C$64,Assumptions!$C$65),IF(35<19,Assumptions!$F$21,Assumptions!$F$22))) -> 6000 | AK13: =IF(36<Assumptions!$C$51,0,IF(Assumptions!$E$5="Test",IF(36<19,Assumptions!$C$64,Assumptions!$C$65),IF(36<19,Assumptions!$F$21,Assumptions!$F$22))) -> 6000
A14: Direct AI paid users | B14: =B13/Assumptions!$C$68 -> 0 | C14: =C13/Assumptions!$C$68 -> 0 | D14: =D13/Assumptions!$C$68 -> 0 | E14: =E13/Assumptions!$C$68 -> 0 | F14: =F13/Assumptions!$C$68 -> 0 | G14: =G13/Assumptions!$C$68 -> 0 | H14: =H13/Assumptions!$C$68 -> 178.57143 | I14: =I13/Assumptions!$C$68 -> 178.57143 | ... AK14: =AK13/Assumptions!$C$68 -> 267.85714
A15: Total new AI users | B15: =SUM(B10:B12,B14) -> 0 | C15: =SUM(C10:C12,C14) -> 0 | D15: =SUM(D10:D12,D14) -> 0 | E15: =SUM(E10:E12,E14) -> 199.86823 | F15: =SUM(F10:F12,F14) -> 199.97126 | G15: =SUM(G10:G12,G14) -> 200.07532 | H15: =SUM(H10:H12,H14) -> 354.8388 | I15: =SUM(I10:I12,I14) -> 354.94496 | ... AK15: =SUM(AK10:AK12,AK14) -> 390.6881
A17: Founding annual users (€69) | B17: =SUM(B10:B11)*Assumptions!$F$11 -> 0 | C17: =SUM(C10:C11)*Assumptions!$F$11 -> 0 | D17: =SUM(D10:D11)*Assumptions!$F$11 -> 0 | E17: =SUM(E10:E11)*Assumptions!$F$11 -> 44.960468 | F17: =SUM(F10:F11)*Assumptions!$F$11 -> 44.991377 | G17: =SUM(G10:G11)*Assumptions!$F$11 -> 45.022595 | H17: =SUM(H10:H11)*Assumptions!$F$11 -> 52.880213 | I17: =SUM(I10:I11)*Assumptions!$F$11 -> 52.912058 | ... AK17: =SUM(AK10:AK11)*Assumptions!$F$11 -> 36.849288
A18: Standard annual users (€89) | B18: =SUM(B12,B14)*Assumptions!$F$11 -> 0 | C18: =SUM(C12,C14)*Assumptions!$F$11 -> 0 | D18: =SUM(D12,D14)*Assumptions!$F$11 -> 0 | E18: =SUM(E12,E14)*Assumptions!$F$11 -> 15 | F18: =SUM(F12,F14)*Assumptions!$F$11 -> 15 | G18: =SUM(G12,G14)*Assumptions!$F$11 -> 15 | H18: =SUM(H12,H14)*Assumptions!$F$11 -> 53.571429 | I18: =SUM(I12,I14)*Assumptions!$F$11 -> 53.571429 | ... AK18: =SUM(AK12,AK14)*Assumptions!$F$11 -> 80.357143
A19: New monthly users (€9) | B19: =B15*(1-Assumptions!$F$11) -> 0 | C19: =C15*(1-Assumptions!$F$11) -> 0 | D19: =D15*(1-Assumptions!$F$11) -> 0 | E19: =E15*(1-Assumptions!$F$11) -> 139.90776 | F19: =F15*(1-Assumptions!$F$11) -> 139.97988 | G19: =G15*(1-Assumptions!$F$11) -> 140.05272 | H19: =H15*(1-Assumptions!$F$11) -> 248.38716 | I19: =I15*(1-Assumptions!$F$11) -> 248.46147 | ... AK19: =AK15*(1-Assumptions!$F$11) -> 273.48167
A20: Annual renewals (€89) | B20: 0 | C20: 0 | D20: 0 | E20: 0 | F20: 0 | G20: 0 | H20: 0 | I20: 0 | J20: 0 | K20: 0 | L20: 0 | M20: 0 | N20: =SUM(B17:B18,B20)*Assumptions!$F$13 -> 0 | O20: =SUM(C17:C18,C20)*Assumptions!$F$13 -> 0 | P20: =SUM(D17:D18,D20)*Assumptions!$F$13 -> 0 | Q20: =SUM(E17:E18,E20)*Assumptions!$F$13 -> 26.982211 | R20: =SUM(F17:F18,F20)*Assumptions!$F$13 -> 26.99612 | S20: =SUM(G17:G18,G20)*Assumptions!$F$13 -> 27.010168 | T20: =SUM(H17:H18,H20)*Assumptions!$F$13 -> 47.903239 | U20: =SUM(I17:I18,I20)*Assumptions!$F$13 -> 47.917569 | ... AK20: =SUM(Y17:Y18,Y20)*Assumptions!$F$13 -> 69.572321
A22: Opening active monthly users | B22: =0 -> 0 | C22: =B24 -> 0 | D22: =C24 -> 0 | E22: =D24 -> 0 | F22: =E24 -> 139.90776 | G22: =F24 -> 268.69502 | H22: =G24 -> 387.25214 | I22: =H24 -> 604.65913 | J22: =I24 -> 804.74787 | ... AK22: =AJ24 -> 3015.4469
A23: Monthly churned users | B23: =-B22*Assumptions!$C$69 -> 0 | C23: =-C22*Assumptions!$C$69 -> 0 | D23: =-D22*Assumptions!$C$69 -> 0 | E23: =-E22*Assumptions!$C$69 -> 0 | F23: =-F22*Assumptions!$C$69 -> -11.192621 | G23: =-G22*Assumptions!$C$69 -> -21.495601 | H23: =-H22*Assumptions!$C$69 -> -30.980171 | I23: =-I22*Assumptions!$C$69 -> -48.372731 | ... AK23: =-AK22*Assumptions!$C$69 -> -241.23575
A24: Closing active monthly users | B24: =SUM(B22:B23,B19) -> 0 | C24: =SUM(C22:C23,C19) -> 0 | D24: =SUM(D22:D23,D19) -> 0 | E24: =SUM(E22:E23,E19) -> 139.90776 | F24: =SUM(F22:F23,F19) -> 268.69502 | G24: =SUM(G22:G23,G19) -> 387.25214 | H24: =SUM(H22:H23,H19) -> 604.65913 | I24: =SUM(I22:I23,I19) -> 804.74787 | ... AK24: =SUM(AK22:AK23,AK19) -> 3047.6929
A25: Active annual users | B25: =SUM(B17:B18)+SUM(B20) -> 0 | C25: =SUM(B17:C18)+SUM(B20:C20) -> 0 | D25: =SUM(B17:D18)+SUM(B20:D20) -> 0 | E25: =SUM(B17:E18)+SUM(B20:E20) -> 59.960468 | F25: =SUM(B17:F18)+SUM(B20:F20) -> 119.95185 | G25: =SUM(B17:G18)+SUM(B20:G20) -> 179.97444 | H25: =SUM(B17:H18)+SUM(B20:H20) -> 286.42608 | I25: =SUM(B17:I18)+SUM(B20:I20) -> 392.90957 | J25: =SUM(B17:J18)+SUM(B20:J20) -> 499.42522 | K25: =SUM(B17:K18)+SUM(B20:K20) -> 585.00584 | L25: =SUM(B17:L18)+SUM(B20:L20) -> 670.65274 | M25: =SUM(B17:M18)+SUM(B20:M20) -> 756.36722 | N25: =SUM(C17:N18)+SUM(C20:N20) -> 844.75936 | O25: =SUM(D17:O18)+SUM(D20:O20) -> 933.22182 | P25: =SUM(E17:P18)+SUM(E20:P20) -> 1021.756 | Q25: =SUM(F17:Q18)+SUM(F20:Q20) -> 1077.3851 | R25: =SUM(G17:R18)+SUM(G20:R20) -> 1133.0719 | S25: =SUM(H17:S18)+SUM(H20:S20) -> 1188.8175 | T25: =SUM(I17:T18)+SUM(I20:T20) -> 1245.8906 | ... AK25: =SUM(Z17:AK18)+SUM(Z20:AK20) -> 2104.7881
A26: Total active AI users | B26: =SUM(B24:B25) -> 0 | C26: =SUM(C24:C25) -> 0 | D26: =SUM(D24:D25) -> 0 | E26: =SUM(E24:E25) -> 199.86823 | F26: =SUM(F24:F25) -> 388.64686 | G26: =SUM(G24:G25) -> 567.22658 | H26: =SUM(H24:H25) -> 891.08521 | I26: =SUM(I24:I25) -> 1197.6574 | ... AK26: =SUM(AK24:AK25) -> 5152.4809
A28: Monthly subscription revenue | B28: =B24*Assumptions!$C$29 -> 0 | C28: =C24*Assumptions!$C$29 -> 0 | D28: =D24*Assumptions!$C$29 -> 0 | E28: =E24*Assumptions!$C$29 -> 1259.1698 | F28: =F24*Assumptions!$C$29 -> 2418.2552 | G28: =G24*Assumptions!$C$29 -> 3485.2693 | H28: =H24*Assumptions!$C$29 -> 5441.9322 | I28: =I24*Assumptions!$C$29 -> 7242.7308 | ... AK28: =AK24*Assumptions!$C$29 -> 27429.236
A29: Founding annual bookings | B29: =B17*Assumptions!$C$31 -> 0 | C29: =C17*Assumptions!$C$31 -> 0 | D29: =D17*Assumptions!$C$31 -> 0 | E29: =E17*Assumptions!$C$31 -> 3102.2723 | F29: =F17*Assumptions!$C$31 -> 3104.405 | G29: =G17*Assumptions!$C$31 -> 3106.5591 | H29: =H17*Assumptions!$C$31 -> 3648.7347 | I29: =I17*Assumptions!$C$31 -> 3650.932 | ... AK29: =AK17*Assumptions!$C$31 -> 2542.6009
A30: Standard annual bookings | B30: =B18*Assumptions!$C$30 -> 0 | C30: =C18*Assumptions!$C$30 -> 0 | D30: =D18*Assumptions!$C$30 -> 0 | E30: =E18*Assumptions!$C$30 -> 1335 | F30: =F18*Assumptions!$C$30 -> 1335 | G30: =G18*Assumptions!$C$30 -> 1335 | H30: =H18*Assumptions!$C$30 -> 4767.8571 | I30: =I18*Assumptions!$C$30 -> 4767.8571 | ... AK30: =AK18*Assumptions!$C$30 -> 7151.7857
A31: Annual renewal bookings | B31: =B20*Assumptions!$C$30 -> 0 | C31: =C20*Assumptions!$C$30 -> 0 | D31: =D20*Assumptions!$C$30 -> 0 | E31: =E20*Assumptions!$C$30 -> 0 | F31: =F20*Assumptions!$C$30 -> 0 | G31: =G20*Assumptions!$C$30 -> 0 | H31: =H20*Assumptions!$C$30 -> 0 | I31: =I20*Assumptions!$C$30 -> 0 | ... AK31: =AK20*Assumptions!$C$30 -> 6191.9366
A32: Total AI revenue | B32: =SUM(B28:B31) -> 0 | C32: =SUM(C28:C31) -> 0 | D32: =SUM(D28:D31) -> 0 | E32: =SUM(E28:E31) -> 5696.4421 | F32: =SUM(F28:F31) -> 6857.6602 | G32: =SUM(G28:G31) -> 7926.8283 | H32: =SUM(H28:H31) -> 13858.524 | I32: =SUM(I28:I31) -> 15661.52 | ... AK32: =SUM(AK28:AK31) -> 43315.559
A34: Monthly contribution | B34: =B24*Assumptions!$C$37 -> 0 | C34: =C24*Assumptions!$C$37 -> 0 | D34: =D24*Assumptions!$C$37 -> 0 | E34: =E24*Assumptions!$C$37 -> 702.40576 | F34: =F24*Assumptions!$C$37 -> 1348.9811 | G34: =G24*Assumptions!$C$37 -> 1944.1962 | H34: =H24*Assumptions!$C$37 -> 3035.6862 | I34: =I24*Assumptions!$C$37 -> 4040.2301 | ... AK34: =AK24*Assumptions!$C$37 -> 15300.917
A35: Discounted annual contribution | B35: =B17*Assumptions!$C$39 -> 0 | C35: =C17*Assumptions!$C$39 -> 0 | D35: =D17*Assumptions!$C$39 -> 0 | E35: =E17*Assumptions!$C$39 -> 1410.7268 | F35: =F17*Assumptions!$C$39 -> 1411.6967 | G35: =G17*Assumptions!$C$39 -> 1412.6762 | H35: =H17*Assumptions!$C$39 -> 1659.225 | I35: =I17*Assumptions!$C$39 -> 1660.2243 | ... AK35: =AK17*Assumptions!$C$39 -> 1156.2219
A36: Standard + renewal annual contribution | B36: =SUM(B18,B20)*Assumptions!$C$38 -> 0 | C36: =SUM(C18,C20)*Assumptions!$C$38 -> 0 | D36: =SUM(D18,D20)*Assumptions!$C$38 -> 0 | E36: =SUM(E18,E20)*Assumptions!$C$38 -> 672.29508 | F36: =SUM(F18,F20)*Assumptions!$C$38 -> 672.29508 | G36: =SUM(G18,G20)*Assumptions!$C$38 -> 672.29508 | H36: =SUM(H18,H20)*Assumptions!$C$38 -> 2401.0539 | I36: =SUM(I18,I20)*Assumptions!$C$38 -> 2401.0539 | ... AK36: =SUM(AK18,AK20)*Assumptions!$C$38 -> 6719.7894
A37: AI contribution before acquisition | B37: =SUM(B34:B36) -> 0 | C37: =SUM(C34:C36) -> 0 | D37: =SUM(D34:D36) -> 0 | E37: =SUM(E34:E36) -> 2785.4277 | F37: =SUM(F34:F36) -> 3432.9729 | G37: =SUM(G34:G36) -> 4029.1675 | H37: =SUM(H34:H36) -> 7095.9651 | I37: =SUM(I34:I36) -> 8101.5082 | ... AK37: =SUM(AK34:AK36) -> 23176.928
A38: Direct AI acquisition spend | B38: =-B13 -> 0 | C38: =-C13 -> 0 | D38: =-D13 -> 0 | E38: =-E13 -> 0 | F38: =-F13 -> 0 | G38: =-G13 -> 0 | H38: =-H13 -> -4000 | I38: =-I13 -> -4000 | ... AK38: =-AK13 -> -6000
A39: AI contribution after acquisition | B39: =SUM(B37:B38) -> 0 | C39: =SUM(C37:C38) -> 0 | D39: =SUM(D37:D38) -> 0 | E39: =SUM(E37:E38) -> 2785.4277 | F39: =SUM(F37:F38) -> 3432.9729 | G39: =SUM(G37:G38) -> 4029.1675 | H39: =SUM(H37:H38) -> 3095.9651 | I39: =SUM(I37:I38) -> 4101.5082 | ... AK39: =SUM(AK37:AK38) -> 17176.928
A41: AI recurring revenue run-rate / month | B41: =B24*Assumptions!$C$29+B25*Assumptions!$C$30/12 -> 0 | C41: =C24*Assumptions!$C$29+C25*Assumptions!$C$30/12 -> 0 | D41: =D24*Assumptions!$C$29+D25*Assumptions!$C$30/12 -> 0 | E41: =E24*Assumptions!$C$29+E25*Assumptions!$C$30/12 -> 1703.8766 | F41: =F24*Assumptions!$C$29+F25*Assumptions!$C$30/12 -> 3307.898 | G41: =G24*Assumptions!$C$29+G25*Assumptions!$C$30/12 -> 4820.0797 | H41: =H24*Assumptions!$C$29+H25*Assumptions!$C$30/12 -> 7566.259 | I41: =I24*Assumptions!$C$29+I25*Assumptions!$C$30/12 -> 10156.81 | ... AK41: =AK24*Assumptions!$C$29+AK25*Assumptions!$C$30/12 -> 43039.747
A42: AI annualized revenue run-rate | B42: =B41*12 -> 0 | C42: =C41*12 -> 0 | D42: =D41*12 -> 0 | E42: =E41*12 -> 20446.52 | F42: =F41*12 -> 39694.776 | G42: =G41*12 -> 57840.956 | H42: =H41*12 -> 90795.107 | I42: =I41*12 -> 121881.72 | ... AK42: =AK41*12 -> 516476.97
A43: Cumulative AI customers acquired | B43: =B15 -> 0 | C43: =B43+C15 -> 0 | D43: =C43+D15 -> 0 | E43: =D43+E15 -> 199.86823 | F43: =E43+F15 -> 399.83948 | G43: =F43+G15 -> 599.9148 | H43: =G43+H15 -> 954.75361 | I43: =H43+I15 -> 1309.6986 | J43: =I43+J15 -> 1664.7507 | ... AK43: =AJ43+AK15 -> 11275.009

Sheet Growth Extensions
A1: TUPENSACI | Growth Extensions
A2: Operating case: relaunch the three existing workbooks and introduce one new workbook every year, plus early B2B pilots. Toggle On/Off in Assumptions!E6.
A5: Month | B5: M1 | C5: M2 | D5: M3 | E5: M4 | F5: M5 | G5: M6 | H5: M7 | I5: M8 | J5: M9 | K5: M10 | L5: M11 | M5: M12 | N5: M13 | O5: M14 | P5: M15 | Q5: M16 | R5: M17 | S5: M18 | T5: M19 | U5: M20 | V5: M21 | W5: M22 | X5: M23 | Y5: M24 | Z5: M25 | AA5: M26 | AB5: M27 | AC5: M28 | AD5: M29 | AE5: M30 | AF5: M31 | AG5: M32 | AH5: M33 | AI5: M34 | AJ5: M35 | AK5: M36
A6: Year | B6: Y1 | C6: Y1 | D6: Y1 | E6: Y1 | F6: Y1 | G6: Y1 | H6: Y1 | I6: Y1 | J6: Y1 | K6: Y1 | L6: Y1 | M6: Y1 | N6: Y2 | O6: Y2 | P6: Y2 | Q6: Y2 | R6: Y2 | S6: Y2 | T6: Y2 | U6: Y2 | V6: Y2 | W6: Y2 | X6: Y2 | Y6: Y2 | Z6: Y3 | AA6: Y3 | AB6: Y3 | AC6: Y3 | AD6: Y3 | AE6: Y3 | AF6: Y3 | AG6: Y3 | AH6: Y3 | AI6: Y3 | AJ6: Y3 | AK6: Y3
A7: Stage | B7: Relaunch | C7: Relaunch | D7: Relaunch | E7: Beta build | F7: Beta build | G7: Gate M6 | H7: AI launch | I7: AI launch | J7: AI launch | K7: Scale test | L7: Scale test | M7: Scale test | N7: Scale | O7: Scale | P7: Scale | Q7: Scale | R7: Scale | S7: Scale | T7: Scale | U7: Scale | V7: Scale | W7: Scale | X7: Scale | Y7: Scale | Z7: Scale | AA7: Scale | AB7: Scale | AC7: Scale | AD7: Scale | AE7: Scale | AF7: Scale | AG7: Scale | AH7: Scale | AI7: Scale | AJ7: Scale | AK7: Scale
A9: NEW WORKBOOK + B2B OPERATING CASE
A10: New workbook organic orders | B10: =IF(Assumptions!$E$6="Off",0,Assumptions!$C$76*(IF(1>=Assumptions!$C$71,1,0)+IF(1>=Assumptions!$C$72,1,0)+IF(1>=Assumptions!$C$73,1,0))) -> 0 | C10: =IF(Assumptions!$E$6="Off",0,Assumptions!$C$76*(IF(2>=Assumptions!$C$71,1,0)+IF(2>=Assumptions!$C$72,1,0)+IF(2>=Assumptions!$C$73,1,0))) -> 0 | D10: =IF(Assumptions!$E$6="Off",0,Assumptions!$C$76*(IF(3>=Assumptions!$C$71,1,0)+IF(3>=Assumptions!$C$72,1,0)+IF(3>=Assumptions!$C$73,1,0))) -> 0 | E10: =IF(Assumptions!$E$6="Off",0,Assumptions!$C$76*(IF(4>=Assumptions!$C$71,1,0)+IF(4>=Assumptions!$C$72,1,0)+IF(4>=Assumptions!$C$73,1,0))) -> 0 | F10: =IF(Assumptions!$E$6="Off",0,Assumptions!$C$76*(IF(5>=Assumptions!$C$71,1,0)+IF(5>=Assumptions!$C$72,1,0)+IF(5>=Assumptions!$C$73,1,0))) -> 0 | G10: =IF(Assumptions!$E$6="Off",0,Assumptions!$C$76*(IF(6>=Assumptions!$C$71,1,0)+IF(6>=Assumptions!$C$72,1,0)+IF(6>=Assumptions!$C$73,1,0))) -> 0 | H10: =IF(Assumptions!$E$6="Off",0,Assumptions!$C$76*(IF(7>=Assumptions!$C$71,1,0)+IF(7>=Assumptions!$C$72,1,0)+IF(7>=Assumptions!$C$73,1,0))) -> 0 | I10: =IF(Assumptions!$E$6="Off",0,Assumptions!$C$76*(IF(8>=Assumptions!$C$71,1,0)+IF(8>=Assumptions!$C$72,1,0)+IF(8>=Assumptions!$C$73,1,0))) -> 0 | J10: =IF(Assumptions!$E$6="Off",0,Assumptions!$C$76*(IF(9>=Assumptions!$C$71,1,0)+IF(9>=Assumptions!$C$72,1,0)+IF(9>=Assumptions!$C$73,1,0))) -> 100 | K10: =IF(Assumptions!$E$6="Off",0,Assumptions!$C$76*(IF(10>=Assumptions!$C$71,1,0)+IF(10>=Assumptions!$C$72,1,0)+IF(10>=Assumptions!$C$73,1,0))) -> 100 | L10: =IF(Assumptions!$E$6="Off",0,Assumptions!$C$76*(IF(11>=Assumptions!$C$71,1,0)+IF(11>=Assumptions!$C$72,1,0)+IF(11>=Assumptions!$C$73,1,0))) -> 100 | M10: =IF(Assumptions!$E$6="Off",0,Assumptions!$C$76*(IF(12>=Assumptions!$C$71,1,0)+IF(12>=Assumptions!$C$72,1,0)+IF(12>=Assumptions!$C$73,1,0))) -> 100 | N10: =IF(Assumptions!$E$6="Off",0,Assumptions!$C$76*(IF(13>=Assumptions!$C$71,1,0)+IF(13>=Assumptions!$C$72,1,0)+IF(13>=Assumptions!$C$73,1,0))) -> 100 | O10: =IF(Assumptions!$E$6="Off",0,Assumptions!$C$76*(IF(14>=Assumptions!$C$71,1,0)+IF(14>=Assumptions!$C$72,1,0)+IF(14>=Assumptions!$C$73,1,0))) -> 100 | P10: =IF(Assumptions!$E$6="Off",0,Assumptions!$C$76*(IF(15>=Assumptions!$C$71,1,0)+IF(15>=Assumptions!$C$72,1,0)+IF(15>=Assumptions!$C$73,1,0))) -> 100 | Q10: =IF(Assumptions!$E$6="Off",0,Assumptions!$C$76*(IF(16>=Assumptions!$C$71,1,0)+IF(16>=Assumptions!$C$72,1,0)+IF(16>=Assumptions!$C$73,1,0))) -> 100 | R10: =IF(Assumptions!$E$6="Off",0,Assumptions!$C$76*(IF(17>=Assumptions!$C$71,1,0)+IF(17>=Assumptions!$C$72,1,0)+IF(17>=Assumptions!$C$73,1,0))) -> 100 | S10: =IF(Assumptions!$E$6="Off",0,Assumptions!$C$76*(IF(18>=Assumptions!$C$71,1,0)+IF(18>=Assumptions!$C$72,1,0)+IF(18>=Assumptions!$C$73,1,0))) -> 100 | T10: =IF(Assumptions!$E$6="Off",0,Assumptions!$C$76*(IF(19>=Assumptions!$C$71,1,0)+IF(19>=Assumptions!$C$72,1,0)+IF(19>=Assumptions!$C$73,1,0))) -> 100 | U10: =IF(Assumptions!$E$6="Off",0,Assumptions!$C$76*(IF(20>=Assumptions!$C$71,1,0)+IF(20>=Assumptions!$C$72,1,0)+IF(20>=Assumptions!$C$73,1,0))) -> 100 | V10: =IF(Assumptions!$E$6="Off",0,Assumptions!$C$76*(IF(21>=Assumptions!$C$71,1,0)+IF(21>=Assumptions!$C$72,1,0)+IF(21>=Assumptions!$C$73,1,0))) -> 200 | W10: =IF(Assumptions!$E$6="Off",0,Assumptions!$C$76*(IF(22>=Assumptions!$C$71,1,0)+IF(22>=Assumptions!$C$72,1,0)+IF(22>=Assumptions!$C$73,1,0))) -> 200 | X10: =IF(Assumptions!$E$6="Off",0,Assumptions!$C$76*(IF(23>=Assumptions!$C$71,1,0)+IF(23>=Assumptions!$C$72,1,0)+IF(23>=Assumptions!$C$73,1,0))) -> 200 | Y10: =IF(Assumptions!$E$6="Off",0,Assumptions!$C$76*(IF(24>=Assumptions!$C$71,1,0)+IF(24>=Assumptions!$C$72,1,0)+IF(24>=Assumptions!$C$73,1,0))) -> 200 | Z10: =IF(Assumptions!$E$6="Off",0,Assumptions!$C$76*(IF(25>=Assumptions!$C$71,1,0)+IF(25>=Assumptions!$C$72,1,0)+IF(25>=Assumptions!$C$73,1,0))) -> 200 | AA10: =IF(Assumptions!$E$6="Off",0,Assumptions!$C$76*(IF(26>=Assumptions!$C$71,1,0)+IF(26>=Assumptions!$C$72,1,0)+IF(26>=Assumptions!$C$73,1,0))) -> 200 | AB10: =IF(Assumptions!$E$6="Off",0,Assumptions!$C$76*(IF(27>=Assumptions!$C$71,1,0)+IF(27>=Assumptions!$C$72,1,0)+IF(27>=Assumptions!$C$73,1,0))) -> 200 | AC10: =IF(Assumptions!$E$6="Off",0,Assumptions!$C$76*(IF(28>=Assumptions!$C$71,1,0)+IF(28>=Assumptions!$C$72,1,0)+IF(28>=Assumptions!$C$73,1,0))) -> 200 | AD10: =IF(Assumptions!$E$6="Off",0,Assumptions!$C$76*(IF(29>=Assumptions!$C$71,1,0)+IF(29>=Assumptions!$C$72,1,0)+IF(29>=Assumptions!$C$73,1,0))) -> 200 | AE10: =IF(Assumptions!$E$6="Off",0,Assumptions!$C$76*(IF(30>=Assumptions!$C$71,1,0)+IF(30>=Assumptions!$C$72,1,0)+IF(30>=Assumptions!$C$73,1,0))) -> 200 | AF10: =IF(Assumptions!$E$6="Off",0,Assumptions!$C$76*(IF(31>=Assumptions!$C$71,1,0)+IF(31>=Assumptions!$C$72,1,0)+IF(31>=Assumptions!$C$73,1,0))) -> 200 | AG10: =IF(Assumptions!$E$6="Off",0,Assumptions!$C$76*(IF(32>=Assumptions!$C$71,1,0)+IF(32>=Assumptions!$C$72,1,0)+IF(32>=Assumptions!$C$73,1,0))) -> 200 | AH10: =IF(Assumptions!$E$6="Off",0,Assumptions!$C$76*(IF(33>=Assumptions!$C$71,1,0)+IF(33>=Assumptions!$C$72,1,0)+IF(33>=Assumptions!$C$73,1,0))) -> 300 | AI10: =IF(Assumptions!$E$6="Off",0,Assumptions!$C$76*(IF(34>=Assumptions!$C$71,1,0)+IF(34>=Assumptions!$C$72,1,0)+IF(34>=Assumptions!$C$73,1,0))) -> 300 | AJ10: =IF(Assumptions!$E$6="Off",0,Assumptions!$C$76*(IF(35>=Assumptions!$C$71,1,0)+IF(35>=Assumptions!$C$72,1,0)+IF(35>=Assumptions!$C$73,1,0))) -> 300 | AK10: =IF(Assumptions!$E$6="Off",0,Assumptions!$C$76*(IF(36>=Assumptions!$C$71,1,0)+IF(36>=Assumptions!$C$72,1,0)+IF(36>=Assumptions!$C$73,1,0))) -> 300
A11: New workbook net revenue | B11: =B10*Assumptions!$C$40 -> 0 | C11: =C10*Assumptions!$C$40 -> 0 | D11: =D10*Assumptions!$C$40 -> 0 | E11: =E10*Assumptions!$C$40 -> 0 | F11: =F10*Assumptions!$C$40 -> 0 | G11: =G10*Assumptions!$C$40 -> 0 | H11: =H10*Assumptions!$C$40 -> 0 | I11: =I10*Assumptions!$C$40 -> 0 | ... AK11: =AK10*Assumptions!$C$40 -> 9600
A12: New workbook print + fulfillment | B12: =-B10*Assumptions!$C$41 -> 0 | C12: =-C10*Assumptions!$C$41 -> 0 | D12: =-D10*Assumptions!$C$41 -> 0 | E12: =-E10*Assumptions!$C$41 -> 0 | F12: =-F10*Assumptions!$C$41 -> 0 | G12: =-G10*Assumptions!$C$41 -> 0 | H12: =-H10*Assumptions!$C$41 -> 0 | I12: =-I10*Assumptions!$C$41 -> 0 | ... AK12: =-AK10*Assumptions!$C$41 -> -3600
A13: New workbook contribution | B13: =SUM(B11:B12) -> 0 | C13: =SUM(C11:C12) -> 0 | D13: =SUM(D11:D12) -> 0 | E13: =SUM(E11:E12) -> 0 | F13: =SUM(F11:F12) -> 0 | G13: =SUM(G11:G12) -> 0 | H13: =SUM(H11:H12) -> 0 | I13: =SUM(I11:I12) -> 0 | ... AK13: =SUM(AK11:AK12) -> 6000
